Workbook
Name A: 'CODIGO-LITERAL'!$B$1:$B$5
Name ACTIVIDAD: 'CODIGO-LITERAL'!$B$6:$B$9
Name B: 'CODIGO-LITERAL'!$B$10:$B$15
Name CALIFICACION_OPERACION: 'CODIGO-LITERAL'!$B$16:$B$19
Name CAUSA_BAJA_BIEN: 'CODIGO-LITERAL'!$B$20:$B$26
Name CLAVE_OPERACION: 'CODIGO-LITERAL'!$B$27:$B$44
Name CLAVE_OPERACION_GASTO: 'CODIGO-LITERAL'!$B$45:$B$57
Name CONCEPTO_GASTO: 'CODIGO-LITERAL'!$B$58:$B$104
Name CONCEPTO_INGRESO: 'CODIGO-LITERAL'!$B$105:$B$113
Name MEDIO_UTILIZADO: 'CODIGO-LITERAL'!$B$114:$B$118
Name METODO_AMORTIZACION: 'CODIGO-LITERAL'!$B$204:$B$213
Name OPERACION_EXENTA: 'CODIGO-LITERAL'!$B$119:$B$124
Name SITUACION: 'CODIGO-LITERAL'!$B$125:$B$129
Name TIPO_BIEN: 'CODIGO-LITERAL'!$B$130:$B$149
Name TIPO_FACTURA: 'CODIGO-LITERAL'!$B$150:$B$161
Name TIPO_FACTURA_GASTO: 'CODIGO-LITERAL'!$B$191:$B$203
Name TIPO_IVA: 'CODIGO-LITERAL'!$B$172:$B$180
Name TIPO_NIF: 'CODIGO-LITERAL'!$B$162:$B$167
Name TIPO_RECARGO_EQUIVALENCIA: 'CODIGO-LITERAL'!$B$181:$B$186
Name TRIMESTRE: 'CODIGO-LITERAL'!$B$168:$B$171

Sheet INSTRUCCIONES
C4: Leyenda de colores
D7: Desplegable del que seleccionar el valor que corresponda
D8: Introducción de valor libre según el formato e instrucciones que se muestran en las ayudas de cada dato
D9: No es necesario introducir el dato
D10: Dato calculado, no es necesario modificarlo

Sheet Registrar expedidas_ingresos
A1: Autoliquidación | C1: Actividad | F1: Tipo de Factura | G1: Concepto de Ingreso | H1: Ingreso Computable | I1: Fecha Expedición | J1: Fecha Operación | K1: Identificación de la Factura | N1: NIF Destinatario | Q1: Nombre Destinatario | R1: Clave de Operación | S1: Calificación de la Operación | T1: Operación Exenta | U1: Total Factura | V1: Base Imponible | W1: Tipo de IVA | X1: Cuota IVA Repercutida | Y1: Tipo de Recargo Eq. | Z1: Cuota Recargo Eq. | AA1: Cobro (Operación Criterio de Caja de IVA y/o artículo 7.2.1º de Reglamento del IRPF) | AE1: Tipo Retención del IRPF | AF1: Importe Retenido del IRPF | AG1: Registro Acuerdo Facturación | AH1: Inmueble | AJ1: Referencia Externa
A2: Ejercicio | B2: Periodo | C2: Código | D2: Tipo | E2: Grupo o Epígrafe del IAE | K2: Serie | L2: Número | M2: Número-Final | N2: Tipo | O2: Código País | P2: Identificación | AA2: Fecha | AB2: Importe | AC2: Medio Utilizado | AD2: Identificación Medio Utilizado | AH2: Situación | AI2: Referencia Catastral
U4: =IF(AND(EXPEDIDAS_INGRESOS!S4="",EXPEDIDAS_INGRESOS!T4=""),"",IF(EXPEDIDAS_INGRESOS!S4="S1",SUM(V4,X4,Z4),V4)) | X4: =IF(OR(V4="",W4=""),"",V4*W4/100) | Z4: =IF(OR(V4="",Y4=""),"",V4*Y4/100)
U5: =IF(AND(EXPEDIDAS_INGRESOS!S5="",EXPEDIDAS_INGRESOS!T5=""),"",IF(EXPEDIDAS_INGRESOS!S5="S1",SUM(V5,X5,Z5),V5)) | Z5: =IF(OR(V5="",Y5=""),"",V5*Y5/100)
U6: =IF(AND(EXPEDIDAS_INGRESOS!S6="",EXPEDIDAS_INGRESOS!T6=""),"",IF(EXPEDIDAS_INGRESOS!S6="S1",SUM(V6,X6,Z6),V6)) | Z6: =IF(OR(V6="",Y6=""),"",V6*Y6/100)
U7: =IF(AND(EXPEDIDAS_INGRESOS!S7="",EXPEDIDAS_INGRESOS!T7=""),"",IF(EXPEDIDAS_INGRESOS!S7="S1",SUM(V7,X7,Z7),V7)) | Z7: =IF(OR(V7="",Y7=""),"",V7*Y7/100)
U8: =IF(AND(EXPEDIDAS_INGRESOS!S8="",EXPEDIDAS_INGRESOS!T8=""),"",IF(EXPEDIDAS_INGRESOS!S8="S1",SUM(V8,X8,Z8),V8)) | Z8: =IF(OR(V8="",Y8=""),"",V8*Y8/100)
U9: =IF(AND(EXPEDIDAS_INGRESOS!S9="",EXPEDIDAS_INGRESOS!T9=""),"",IF(EXPEDIDAS_INGRESOS!S9="S1",SUM(V9,X9,Z9),V9)) | Z9: =IF(OR(V9="",Y9=""),"",V9*Y9/100)
U10: =IF(AND(EXPEDIDAS_INGRESOS!S10="",EXPEDIDAS_INGRESOS!T10=""),"",IF(EXPEDIDAS_INGRESOS!S10="S1",SUM(V10,X10,Z10),V10)) | Z10: =IF(OR(V10="",Y10=""),"",V10*Y10/100)
U11: =IF(AND(EXPEDIDAS_INGRESOS!S11="",EXPEDIDAS_INGRESOS!T11=""),"",IF(EXPEDIDAS_INGRESOS!S11="S1",SUM(V11,X11,Z11),V11)) | Z11: =IF(OR(V11="",Y11=""),"",V11*Y11/100)
U12: =IF(AND(EXPEDIDAS_INGRESOS!S12="",EXPEDIDAS_INGRESOS!T12=""),"",IF(EXPEDIDAS_INGRESOS!S12="S1",SUM(V12,X12,Z12),V12)) | Z12: =IF(OR(V12="",Y12=""),"",V12*Y12/100)
U13: =IF(AND(EXPEDIDAS_INGRESOS!S13="",EXPEDIDAS_INGRESOS!T13=""),"",IF(EXPEDIDAS_INGRESOS!S13="S1",SUM(V13,X13,Z13),V13)) | Z13: =IF(OR(V13="",Y13=""),"",V13*Y13/100)
U14: =IF(AND(EXPEDIDAS_INGRESOS!S14="",EXPEDIDAS_INGRESOS!T14=""),"",IF(EXPEDIDAS_INGRESOS!S14="S1",SUM(V14,X14,Z14),V14)) | Z14: =IF(OR(V14="",Y14=""),"",V14*Y14/100)
U15: =IF(AND(EXPEDIDAS_INGRESOS!S15="",EXPEDIDAS_INGRESOS!T15=""),"",IF(EXPEDIDAS_INGRESOS!S15="S1",SUM(V15,X15,Z15),V15)) | Z15: =IF(OR(V15="",Y15=""),"",V15*Y15/100)
U16: =IF(AND(EXPEDIDAS_INGRESOS!S16="",EXPEDIDAS_INGRESOS!T16=""),"",IF(EXPEDIDAS_INGRESOS!S16="S1",SUM(V16,X16,Z16),V16)) | Z16: =IF(OR(V16="",Y16=""),"",V16*Y16/100)
... U103: =IF(AND(EXPEDIDAS_INGRESOS!S103="",EXPEDIDAS_INGRESOS!T103=""),"",IF(EXPEDIDAS_INGRESOS!S103="S1",SUM(V103,X103,Z103),V103)) | Z103: =IF(OR(V103="",Y103=""),"",V103*Y103/100)

Sheet Registrar recibidas_gastos
A1: Autoliquidación | C1: Actividad | F1: Tipo de Factura | G1: Concepto de Gasto | H1: Gasto Deducible | I1: Fecha Expedición | J1: Fecha Operación | K1: Identificación Factura del Expedidor | M1: Fecha Recepción | N1: Número Recepción | O1: Número Recepción Final | P1: NIF Expedidor | S1: Nombre Expedidor | T1: Clave de Operación | U1: Bien de Inversión | V1: Inversión del Sujeto Pasivo | W1: Deducible en Periodo Posterior | X1: Periodo Deducción | Z1: Total Factura | AA1: Base Imponible | AB1: Tipo de IVA | AC1: Cuota IVA Soportado | AD1: Cuota Deducible | AE1: Tipo de Recargo Eq. | AF1: Cuota Recargo Eq. | AG1: Pago (Operación Criterio de Caja de IVA y/o artículo 7.2.1º de Reglamento del IRPF) | AK1: Tipo Retención del IRPF | AL1: Importe Retenido del IRPF | AM1: Registro Acuerdo Facturación | AN1: Inmueble | AP1: Referencia Externa
A2: Ejercicio | B2: Periodo | C2: Código | D2: Tipo | E2: Grupo o Epígrafe del IAE | K2: (Serie-Número) | L2: Número-Final | P2: Tipo | Q2: Código País | R2: Identificación | X2: Ejercicio | Y2: Periodo | AG2: Fecha | AH2: Importe | AI2: Medio Utilizado | AJ2: Identificación Medio Utilizado | AN2: Situación | AO2: Referencia Catastral
N4: =IF(RECIBIDAS_GASTOS!F4="","",CONCATENATE(RECIBIDAS_GASTOS!F4,"-",COUNTIF(RECIBIDAS_GASTOS!F:F,RECIBIDAS_GASTOS!F4))) | O4: =IF(RECIBIDAS_GASTOS!F4="","",CONCATENATE(RECIBIDAS_GASTOS!F4,"-",COUNTIF(RECIBIDAS_GASTOS!F:F,RECIBIDAS_GASTOS!F4))) | Z4: =IF(AA4="","",IF(AND(F4="",T4=""),"",IF(OR(LEFT(T4,2)="03",LEFT(T4,2)="05",LEFT(T4,2)="09"),AA4,SUM(AA4,AC4,AF4)))) | AC4: =IF(OR(AA4="",AB4=""),"",AA4*AB4/100) | AF4: =IF(OR(AA4="",AE4=""),"",AA4*AE4/100)
N5: =IF(RECIBIDAS_GASTOS!F5="","",CONCATENATE(RECIBIDAS_GASTOS!F5,"-",COUNTIF(RECIBIDAS_GASTOS!F:F,RECIBIDAS_GASTOS!F5))) | O5: =IF(RECIBIDAS_GASTOS!F5="","",CONCATENATE(RECIBIDAS_GASTOS!F5,"-",COUNTIF(RECIBIDAS_GASTOS!F:F,RECIBIDAS_GASTOS!F5))) | Z5: =IF(AA5="","",IF(AND(F5="",T5=""),"",IF(OR(LEFT(T5,2)="03",LEFT(T5,2)="05",LEFT(T5,2)="09"),AA5,SUM(AA5,AC5,AF5)))) | AC5: =IF(OR(AA5="",AB5=""),"",AA5*AB5/100) | AF5: =IF(OR(AA5="",AE5=""),"",AA5*AE5/100)
N6: =IF(RECIBIDAS_GASTOS!F6="","",CONCATENATE(RECIBIDAS_GASTOS!F6,"-",COUNTIF(RECIBIDAS_GASTOS!F:F,RECIBIDAS_GASTOS!F6))) | O6: =IF(RECIBIDAS_GASTOS!F6="","",CONCATENATE(RECIBIDAS_GASTOS!F6,"-",COUNTIF(RECIBIDAS_GASTOS!F:F,RECIBIDAS_GASTOS!F6))) | Z6: =IF(AA6="","",IF(AND(F6="",T6=""),"",IF(OR(LEFT(T6,2)="03",LEFT(T6,2)="05",LEFT(T6,2)="09"),AA6,SUM(AA6,AC6,AF6)))) | AC6: =IF(OR(AA6="",AB6=""),"",AA6*AB6/100) | AF6: =IF(OR(AA6="",AE6=""),"",AA6*AE6/100)
N7: =IF(RECIBIDAS_GASTOS!F7="","",CONCATENATE(RECIBIDAS_GASTOS!F7,"-",COUNTIF(RECIBIDAS_GASTOS!F:F,RECIBIDAS_GASTOS!F7))) | O7: =IF(RECIBIDAS_GASTOS!F7="","",CONCATENATE(RECIBIDAS_GASTOS!F7,"-",COUNTIF(RECIBIDAS_GASTOS!F:F,RECIBIDAS_GASTOS!F7))) | Z7: =IF(AA7="","",IF(AND(F7="",T7=""),"",IF(OR(LEFT(T7,2)="03",LEFT(T7,2)="05",LEFT(T7,2)="09"),AA7,SUM(AA7,AC7,AF7)))) | AC7: =IF(OR(AA7="",AB7=""),"",AA7*AB7/100) | AF7: =IF(OR(AA7="",AE7=""),"",AA7*AE7/100)
N8: =IF(RECIBIDAS_GASTOS!F8="","",CONCATENATE(RECIBIDAS_GASTOS!F8,"-",COUNTIF(RECIBIDAS_GASTOS!F:F,RECIBIDAS_GASTOS!F8))) | O8: =IF(RECIBIDAS_GASTOS!F8="","",CONCATENATE(RECIBIDAS_GASTOS!F8,"-",COUNTIF(RECIBIDAS_GASTOS!F:F,RECIBIDAS_GASTOS!F8))) | Z8: =IF(AA8="","",IF(AND(F8="",T8=""),"",IF(OR(LEFT(T8,2)="03",LEFT(T8,2)="05",LEFT(T8,2)="09"),AA8,SUM(AA8,AC8,AF8)))) | AC8: =IF(OR(AA8="",AB8=""),"",AA8*AB8/100) | AF8: =IF(OR(AA8="",AE8=""),"",AA8*AE8/100)
N9: =IF(RECIBIDAS_GASTOS!F9="","",CONCATENATE(RECIBIDAS_GASTOS!F9,"-",COUNTIF(RECIBIDAS_GASTOS!F:F,RECIBIDAS_GASTOS!F9))) | O9: =IF(RECIBIDAS_GASTOS!F9="","",CONCATENATE(RECIBIDAS_GASTOS!F9,"-",COUNTIF(RECIBIDAS_GASTOS!F:F,RECIBIDAS_GASTOS!F9))) | Z9: =IF(AA9="","",IF(AND(F9="",T9=""),"",IF(OR(LEFT(T9,2)="03",LEFT(T9,2)="05",LEFT(T9,2)="09"),AA9,SUM(AA9,AC9,AF9)))) | AC9: =IF(OR(AA9="",AB9=""),"",AA9*AB9/100) | AF9: =IF(OR(AA9="",AE9=""),"",AA9*AE9/100)
N10: =IF(RECIBIDAS_GASTOS!F10="","",CONCATENATE(RECIBIDAS_GASTOS!F10,"-",COUNTIF(RECIBIDAS_GASTOS!F:F,RECIBIDAS_GASTOS!F10))) | O10: =IF(RECIBIDAS_GASTOS!F10="","",CONCATENATE(RECIBIDAS_GASTOS!F10,"-",COUNTIF(RECIBIDAS_GASTOS!F:F,RECIBIDAS_GASTOS!F10))) | Z10: =IF(AA10="","",IF(AND(F10="",T10=""),"",IF(OR(LEFT(T10,2)="03",LEFT(T10,2)="05",LEFT(T10,2)="09"),AA10,SUM(AA10,AC10,AF10)))) | AC10: =IF(OR(AA10="",AB10=""),"",AA10*AB10/100) | AF10: =IF(OR(AA10="",AE10=""),"",AA10*AE10/100)
N11: =IF(RECIBIDAS_GASTOS!F11="","",CONCATENATE(RECIBIDAS_GASTOS!F11,"-",COUNTIF(RECIBIDAS_GASTOS!F:F,RECIBIDAS_GASTOS!F11))) | O11: =IF(RECIBIDAS_GASTOS!F11="","",CONCATENATE(RECIBIDAS_GASTOS!F11,"-",COUNTIF(RECIBIDAS_GASTOS!F:F,RECIBIDAS_GASTOS!F11))) | Z11: =IF(AA11="","",IF(AND(F11="",T11=""),"",IF(OR(LEFT(T11,2)="03",LEFT(T11,2)="05",LEFT(T11,2)="09"),AA11,SUM(AA11,AC11,AF11)))) | AC11: =IF(OR(AA11="",AB11=""),"",AA11*AB11/100) | AF11: =IF(OR(AA11="",AE11=""),"",AA11*AE11/100)
N12: =IF(RECIBIDAS_GASTOS!F12="","",CONCATENATE(RECIBIDAS_GASTOS!F12,"-",COUNTIF(RECIBIDAS_GASTOS!F:F,RECIBIDAS_GASTOS!F12))) | O12: =IF(RECIBIDAS_GASTOS!F12="","",CONCATENATE(RECIBIDAS_GASTOS!F12,"-",COUNTIF(RECIBIDAS_GASTOS!F:F,RECIBIDAS_GASTOS!F12))) | Z12: =IF(AA12="","",IF(AND(F12="",T12=""),"",IF(OR(LEFT(T12,2)="03",LEFT(T12,2)="05",LEFT(T12,2)="09"),AA12,SUM(AA12,AC12,AF12)))) | AC12: =IF(OR(AA12="",AB12=""),"",AA12*AB12/100) | AF12: =IF(OR(AA12="",AE12=""),"",AA12*AE12/100)
N13: =IF(RECIBIDAS_GASTOS!F13="","",CONCATENATE(RECIBIDAS_GASTOS!F13,"-",COUNTIF(RECIBIDAS_GASTOS!F:F,RECIBIDAS_GASTOS!F13))) | O13: =IF(RECIBIDAS_GASTOS!F13="","",CONCATENATE(RECIBIDAS_GASTOS!F13,"-",COUNTIF(RECIBIDAS_GASTOS!F:F,RECIBIDAS_GASTOS!F13))) | Z13: =IF(AA13="","",IF(AND(F13="",T13=""),"",IF(OR(LEFT(T13,2)="03",LEFT(T13,2)="05",LEFT(T13,2)="09"),AA13,SUM(AA13,AC13,AF13)))) | AC13: =IF(OR(AA13="",AB13=""),"",AA13*AB13/100) | AF13: =IF(OR(AA13="",AE13=""),"",AA13*AE13/100)
N14: =IF(RECIBIDAS_GASTOS!F14="","",CONCATENATE(RECIBIDAS_GASTOS!F14,"-",COUNTIF(RECIBIDAS_GASTOS!F:F,RECIBIDAS_GASTOS!F14))) | O14: =IF(RECIBIDAS_GASTOS!F14="","",CONCATENATE(RECIBIDAS_GASTOS!F14,"-",COUNTIF(RECIBIDAS_GASTOS!F:F,RECIBIDAS_GASTOS!F14))) | Z14: =IF(AA14="","",IF(AND(F14="",T14=""),"",IF(OR(LEFT(T14,2)="03",LEFT(T14,2)="05",LEFT(T14,2)="09"),AA14,SUM(AA14,AC14,AF14)))) | AC14: =IF(OR(AA14="",AB14=""),"",AA14*AB14/100) | AF14: =IF(OR(AA14="",AE14=""),"",AA14*AE14/100)
N15: =IF(RECIBIDAS_GASTOS!F15="","",CONCATENATE(RECIBIDAS_GASTOS!F15,"-",COUNTIF(RECIBIDAS_GASTOS!F:F,RECIBIDAS_GASTOS!F15))) | O15: =IF(RECIBIDAS_GASTOS!F15="","",CONCATENATE(RECIBIDAS_GASTOS!F15,"-",COUNTIF(RECIBIDAS_GASTOS!F:F,RECIBIDAS_GASTOS!F15))) | Z15: =IF(AA15="","",IF(AND(F15="",T15=""),"",IF(OR(LEFT(T15,2)="03",LEFT(T15,2)="05",LEFT(T15,2)="09"),AA15,SUM(AA15,AC15,AF15)))) | AC15: =IF(OR(AA15="",AB15=""),"",AA15*AB15/100) | AF15: =IF(OR(AA15="",AE15=""),"",AA15*AE15/100)
... N103: =IF(RECIBIDAS_GASTOS!F103="","",CONCATENATE(RECIBIDAS_GASTOS!F103,"-",COUNTIF(RECIBIDAS_GASTOS!F:F,RECIBIDAS_GASTOS!F103))) | O103: =IF(RECIBIDAS_GASTOS!F103="","",CONCATENATE(RECIBIDAS_GASTOS!F103,"-",COUNTIF(RECIBIDAS_GASTOS!F:F,RECIBIDAS_GASTOS!F103))) | Z103: =IF(AA103="","",IF(AND(F103="",T103=""),"",IF(OR(LEFT(T103,2)="03",LEFT(T103,2)="05",LEFT(T103,2)="09"),AA103,SUM(AA103,AC103,AF103)))) | AC103: =IF(OR(AA103="",AB103=""),"",AA103*AB103/100) | AF103: =IF(OR(AA103="",AE103=""),"",AA103*AE103/100)

Sheet Registrar bienes de inversión
A1: Autoliquidación | C1: Actividad | F1: Tipo de Bien | G1: Descripción del Bien | I1: Fecha Inicio Utilización | J1: Valor Adquisición | K1: Valor Amortizable | L1: Método de Amortización | M1: Porcentaje de Amortización | N1: Amortización | R1: Fecha Expedición | S1: Identificación Factura del Expedidor | U1: Número Recepción | V1: Número Recepción Final | W1: NIF Expedidor | Z1: Nombre Expedidor | AA1: Año de Inicio Utilización | AE1: Regularización Anual | AH1: Baja del Bien | AJ1: Identificación de la Factura de Transmisión del Bien | AM1: Registro Acuerdo Facturación | AN1: Inmueble | AP1: Referencia Externa
A2: Ejercicio | B2: Periodo | C2: Código | D2: Tipo | E2: Grupo o Epígrafe del IAE | G2: Identificador | H2: Literal | N2: Acumulada al Inicio | O2: Cuota Resultante | P2: Acumulada al final | Q2: Pendiente | S2: (Serie-Número) | T2: Número-Final | W2: Tipo | X2: Código País | Y2: Identificación | AA2: Base Imponible | AB2: Tipo de IVA | AC2: Prorrata Definitiva | AD2: Cuota Deducible | AE2: Prorrata Definitiva | AF2: Cuota Deducible | AG2: Cuota a Regularizar | AH2: Fecha | AI2: Causa | AJ2: Serie | AK2: Número | AL2: Número-Final | AN2: Situación | AO2: Referencia Catastral

Sheet EXPEDIDAS_INGRESOS
A1: Autoliquidación | C1: Actividad | F1: Tipo de Factura | G1: Concepto de Ingreso | H1: Ingreso Computable | I1: Fecha Expedición | J1: Fecha Operación | K1: Identificación de la Factura | N1: NIF Destinatario | Q1: Nombre Destinatario | R1: Clave de Operación | S1: Calificación de la Operación | T1: Operación Exenta | U1: Total Factura | V1: Base Imponible | W1: Tipo de IVA | X1: Cuota IVA Repercutida | Y1: Tipo de Recargo Eq. | Z1: Cuota Recargo Eq. | AA1: Cobro (Operación Criterio de Caja de IVA y/o artículo 7.2.1º de Reglamento del IRPF) | AE1: Tipo Retención del IRPF | AF1: Importe Retenido del IRPF | AG1: Registro Acuerdo Facturación | AH1: Inmueble | AJ1: Refrencia Externa
A2: Ejercicio | B2: Periodo | C2: Código | D2: Tipo | E2: Grupo o Epígrafe del IAE | K2: Serie | L2: Número | M2: Número-Final | N2: Tipo | O2: Código País | P2: Identificación | AA2: Fecha | AB2: Importe | AC2: Medio Utilizado | AD2: Identificación Medio Utilizado | AH2: Situación | AI2: Referencia Catastral
A3: Decimal (4,0) | B3: Alfanumérico (2) | C3: Alfanumérico (1) | D3: Alfanumérico (2) | E3: Alfanumérico (4) | F3: Alfanumérico (2) | G3: Alfanumérico (3) | H3: Decimal(12,2) | I3: Fecha(dd/mm/yyyy) | J3: Fecha(dd/mm/yyyy) | K3: Alfanumérico (20) | L3: Alfanumérico (20) | M3: Alfanumérico (20) | N3: Alfanumérico (2) | O3: Alfanumérico (2) | P3: Alfanumérico (20) | Q3: Alfanumérico (40) | R3: Alfanumérico (2) | S3: Alfanumérico (2) | T3: Alfanumérico (2) | U3: Decimal(12,2) | V3: Decimal(12,2) | W3: Decimal(4,2) | X3: Decimal(12,2) | Y3: Decimal(4,2) | Z3: Decimal(12,2) | AA3: Fecha(dd/mm/yyyy) | AB3: Decimal(12,2) | AC3: Alfanumérico (2) | AD3: Alfanumérico (34) | AE3: Decimal(4,2) | AF3: Decimal(12,2) | AG3: Alfanumérico (15) | AH3: Alfanumérico (1) | AI3: Alfanumérico (20) | AJ3: Alfanumérico (40)
A4: =IF('Registrar expedidas_ingresos'!J4="",IF('Registrar expedidas_ingresos'!I4="","",YEAR('Registrar expedidas_ingresos'!I4)),YEAR('Registrar expedidas_ingresos'!J4)) | B4: =IF('Registrar expedidas_ingresos'!B4="","",'Registrar expedidas_ingresos'!B4) | C4: =IF('Registrar expedidas_ingresos'!C4="","",VLOOKUP(CONCATENATE("ACTIVIDAD",'Registrar expedidas_ingresos'!C4),'CODIGO-LITERAL'!C:D,2,FALSE)) | D4: =IF(OR(C4="C",C4="D"),"",IF(ISERROR(VLOOKUP(CONCATENATE(C4,'Registrar expedidas_ingresos'!D4),'CODIGO-LITERAL'!$C:$D,2,FALSE)),"",VLOOKUP(CONCATENATE(C4,'Registrar expedidas_ingresos'!D4),'CODIGO-LITERAL'!$C:$D,2,FALSE))) | E4: =IF('Registrar expedidas_ingresos'!E4="","",'Registrar expedidas_ingresos'!E4) | F4: =IF(ISERROR(VLOOKUP(CONCATENATE("TIPO FACTURA",'Registrar expedidas_ingresos'!F4),'CODIGO-LITERAL'!$C:$D,2,FALSE)),"",VLOOKUP(CONCATENATE("TIPO FACTURA",'Registrar expedidas_ingresos'!F4),'CODIGO-LITERAL'!$C:$D,2,FALSE)) | I4: =IF('Registrar expedidas_ingresos'!I4="","",'Registrar expedidas_ingresos'!I4) | J4: =IF('Registrar expedidas_ingresos'!J4="","",'Registrar expedidas_ingresos'!J4) | K4: =IF('Registrar expedidas_ingresos'!K4="","",'Registrar expedidas_ingresos'!K4) | L4: =IF('Registrar expedidas_ingresos'!L4="","",'Registrar expedidas_ingresos'!L4) | M4: =IF('Registrar expedidas_ingresos'!M4="","",'Registrar expedidas_ingresos'!M4) | N4: =IF(OR(F4="F2",LEFT('Registrar expedidas_ingresos'!N4,2)="01"),"",IF(ISERROR(VLOOKUP(CONCATENATE("TIPO NIF",'Registrar expedidas_ingresos'!N4),'CODIGO-LITERAL'!$C:$D,2,FALSE)),"",VLOOKUP(CONCATENATE("TIPO NIF",'Registrar expedidas_ingresos'!N4),'CODIGO-LITERAL'!$C:$D,2,FALSE))) | O4: =IF(OR('Registrar expedidas_ingresos'!O4="",N4="02",F4="F2"),"",'Registrar expedidas_ingresos'!O4) | P4: =IF('Registrar expedidas_ingresos'!P4="","",'Registrar expedidas_ingresos'!P4) | Q4: =IF(F4="F2","VENTAS A CONSUMIDOR FINAL",IF('Registrar expedidas_ingresos'!Q4="","",'Registrar expedidas_ingresos'!Q4)) | R4: =IF(F4="DV","02",IF(ISERROR(VLOOKUP(CONCATENATE("CLAVE OPERACION",'Registrar expedidas_ingresos'!R4),'CODIGO-LITERAL'!$C:$D,2,FALSE)),"",VLOOKUP(CONCATENATE("CLAVE OPERACION",'Registrar expedidas_ingresos'!R4),'CODIGO-LITERAL'!$C:$D,2,FALSE))) | S4: =IF(R4="03","S1", IF(R4="08","N2", IF(ISERROR(VLOOKUP(CONCATENATE("CALIFICACION OPERACION",'Registrar expedidas_ingresos'!S4),'CODIGO-LITERAL'!$C:$D,2,FALSE)),"",VLOOKUP(CONCATENATE("CALIFICACION OPERACION",'Registrar expedidas_ingresos'!S4),'CODIGO-LITERAL'!$C:$D,2,FALSE)))) | T4: =IF(R4="03","",IF(R4="08","",IF(ISERROR(VLOOKUP(CONCATENATE("OPERACION EXENTA",'Registrar expedidas_ingresos'!T4),'CODIGO-LITERAL'!$C:$D,2,FALSE)),"",VLOOKUP(CONCATENATE("OPERACION EXENTA",'Registrar expedidas_ingresos'!T4),'CODIGO-LITERAL'!$C:$D,2,FALSE)))) | U4: =IF(AND(S4="",T4=""),"",IF(S4="S1",ROUND(SUM(V4,X4,Z4),2),ROUND(V4,2))) | V4: =IF('Registrar expedidas_ingresos'!V4="","",ROUND('Registrar expedidas_ingresos'!V4,2)) | W4: =IF(S4="S2",0,IF('Registrar expedidas_ingresos'!W4="","",'Registrar expedidas_ingresos'!W4)) | X4: =IF(S4="S2",0,IF('Registrar expedidas_ingresos'!X4="","",ROUND('Registrar expedidas_ingresos'!X4,2))) | Y4: =IF('Registrar expedidas_ingresos'!Y4="","",'Registrar expedidas_ingresos'!Y4) | Z4: =IF('Registrar expedidas_ingresos'!Z4="","",ROUND('Registrar expedidas_ingresos'!Z4,2)) | AA4: =IF(R4<>"07","",IF('Registrar expedidas_ingresos'!AA4="","",'Registrar expedidas_ingresos'!AA4)) | AB4: =IF(R4<>"07","",IF('Registrar expedidas_ingresos'!AB4="","",'Registrar expedidas_ingresos'!AB4)) | AC4: =IF(R4<>"07","",IF(ISERROR(VLOOKUP(CONCATENATE("MEDIO UTILIZADO",'Registrar expedidas_ingresos'!AC4),'CODIGO-LITERAL'!$C:$D,2,FALSE)),"",VLOOKUP(CONCATENATE("MEDIO UTILIZADO",'Registrar expedidas_ingresos'!AC4),'CODIGO-LITERAL'!$C:$D,2,FALSE))) | AD4: =IF(R4<>"07","",IF('Registrar expedidas_ingresos'!AD4="","",'Registrar expedidas_ingresos'!AD4)) | AG4: =IF('Registrar expedidas_ingresos'!AG4="","",'Registrar expedidas_ingresos'!AG4) | AH4: =IF(ISERROR(VLOOKUP(CONCATENATE("SITUACION",'Registrar expedidas_ingresos'!AH4),'CODIGO-LITERAL'!$C:$D,2,FALSE)),"",VLOOKUP(CONCATENATE("SITUACION",'Registrar expedidas_ingresos'!AH4),'CODIGO-LITERAL'!$C:$D,2,FALSE)) | AI4: =IF('Registrar expedidas_ingresos'!AI4="","",'Registrar expedidas_ingresos'!AI4) | AJ4: =IF('Registrar expedidas_ingresos'!AJ4="","",'Registrar expedidas_ingresos'!AJ4)
A5: =IF('Registrar expedidas_ingresos'!J5="",IF('Registrar expedidas_ingresos'!I5="","",YEAR('Registrar expedidas_ingresos'!I5)),YEAR('Registrar expedidas_ingresos'!J5)) | B5: =IF('Registrar expedidas_ingresos'!B5="","",'Registrar expedidas_ingresos'!B5) | C5: =IF('Registrar expedidas_ingresos'!C5="","",VLOOKUP(CONCATENATE("ACTIVIDAD",'Registrar expedidas_ingresos'!C5),'CODIGO-LITERAL'!C:D,2,FALSE)) | D5: =IF(OR(C5="C",C5="D"),"",IF(ISERROR(VLOOKUP(CONCATENATE(C5,'Registrar expedidas_ingresos'!D5),'CODIGO-LITERAL'!$C:$D,2,FALSE)),"",VLOOKUP(CONCATENATE(C5,'Registrar expedidas_ingresos'!D5),'CODIGO-LITERAL'!$C:$D,2,FALSE))) | E5: =IF('Registrar expedidas_ingresos'!E5="","",'Registrar expedidas_ingresos'!E5) | F5: =IF(ISERROR(VLOOKUP(CONCATENATE("TIPO FACTURA",'Registrar expedidas_ingresos'!F5),'CODIGO-LITERAL'!$C:$D,2,FALSE)),"",VLOOKUP(CONCATENATE("TIPO FACTURA",'Registrar expedidas_ingresos'!F5),'CODIGO-LITERAL'!$C:$D,2,FALSE)) | I5: =IF('Registrar expedidas_ingresos'!I5="","",'Registrar expedidas_ingresos'!I5) | J5: =IF('Registrar expedidas_ingresos'!J5="","",'Registrar expedidas_ingresos'!J5) | K5: =IF('Registrar expedidas_ingresos'!K5="","",'Registrar expedidas_ingresos'!K5) | L5: =IF('Registrar expedidas_ingresos'!L5="","",'Registrar expedidas_ingresos'!L5) | M5: =IF('Registrar expedidas_ingresos'!M5="","",'Registrar expedidas_ingresos'!M5) | N5: =IF(OR(F5="F2",LEFT('Registrar expedidas_ingresos'!N5,2)="01"),"",IF(ISERROR(VLOOKUP(CONCATENATE("TIPO NIF",'Registrar expedidas_ingresos'!N5),'CODIGO-LITERAL'!$C:$D,2,FALSE)),"",VLOOKUP(CONCATENATE("TIPO NIF",'Registrar expedidas_ingresos'!N5),'CODIGO-LITERAL'!$C:$D,2,FALSE))) | O5: =IF(OR('Registrar expedidas_ingresos'!O5="",N5="02",F5="F2"),"",'Registrar expedidas_ingresos'!O5) | P5: =IF('Registrar expedidas_ingresos'!P5="","",'Registrar expedidas_ingresos'!P5) | Q5: =IF(F5="F2","VENTAS A CONSUMIDOR FINAL",IF('Registrar expedidas_ingresos'!Q5="","",'Registrar expedidas_ingresos'!Q5)) | R5: =IF(F5="DV","02",IF(ISERROR(VLOOKUP(CONCATENATE("CLAVE OPERACION",'Registrar expedidas_ingresos'!R5),'CODIGO-LITERAL'!$C:$D,2,FALSE)),"",VLOOKUP(CONCATENATE("CLAVE OPERACION",'Registrar expedidas_ingresos'!R5),'CODIGO-LITERAL'!$C:$D,2,FALSE))) | S5: =IF(R5="03","S1", IF(R5="08","N2", IF(ISERROR(VLOOKUP(CONCATENATE("CALIFICACION OPERACION",'Registrar expedidas_ingresos'!S5),'CODIGO-LITERAL'!$C:$D,2,FALSE)),"",VLOOKUP(CONCATENATE("CALIFICACION OPERACION",'Registrar expedidas_ingresos'!S5),'CODIGO-LITERAL'!$C:$D,2,FALSE)))) | T5: =IF(R5="03","",IF(R5="08","",IF(ISERROR(VLOOKUP(CONCATENATE("OPERACION EXENTA",'Registrar expedidas_ingresos'!T5),'CODIGO-LITERAL'!$C:$D,2,FALSE)),"",VLOOKUP(CONCATENATE("OPERACION EXENTA",'Registrar expedidas_ingresos'!T5),'CODIGO-LITERAL'!$C:$D,2,FALSE)))) | U5: =IF(AND(S5="",T5=""),"",IF(S5="S1",ROUND(SUM(V5,X5,Z5),2),ROUND(V5,2))) | V5: =IF('Registrar expedidas_ingresos'!V5="","",ROUND('Registrar expedidas_ingresos'!V5,2)) | W5: =IF(S5="S2",0,IF('Registrar expedidas_ingresos'!W5="","",'Registrar expedidas_ingresos'!W5)) | X5: =IF(S5="S2",0,IF('Registrar expedidas_ingresos'!X5="","",ROUND('Registrar expedidas_ingresos'!X5,2))) | Y5: =IF('Registrar expedidas_ingresos'!Y5="","",'Registrar expedidas_ingresos'!Y5) | Z5: =IF('Registrar expedidas_ingresos'!Z5="","",ROUND('Registrar expedidas_ingresos'!Z5,2)) | AA5: =IF(R5<>"07","",IF('Registrar expedidas_ingresos'!AA5="","",'Registrar expedidas_ingresos'!AA5)) | AB5: =IF(R5<>"07","",IF('Registrar expedidas_ingresos'!AB5="","",'Registrar expedidas_ingresos'!AB5)) | AC5: =IF(R5<>"07","",IF(ISERROR(VLOOKUP(CONCATENATE("MEDIO UTILIZADO",'Registrar expedidas_ingresos'!AC5),'CODIGO-LITERAL'!$C:$D,2,FALSE)),"",VLOOKUP(CONCATENATE("MEDIO UTILIZADO",'Registrar expedidas_ingresos'!AC5),'CODIGO-LITERAL'!$C:$D,2,FALSE))) | AD5: =IF(R5<>"07","",IF('Registrar expedidas_ingresos'!AD5="","",'Registrar expedidas_ingresos'!AD5)) | AG5: =IF('Registrar expedidas_ingresos'!AG5="","",'Registrar expedidas_ingresos'!AG5) | AH5: =IF(ISERROR(VLOOKUP(CONCATENATE("SITUACION",'Registrar expedidas_ingresos'!AH5),'CODIGO-LITERAL'!$C:$D,2,FALSE)),"",VLOOKUP(CONCATENATE("SITUACION",'Registrar expedidas_ingresos'!AH5),'CODIGO-LITERAL'!$C:$D,2,FALSE)) | AI5: =IF('Registrar expedidas_ingresos'!AI5="","",'Registrar expedidas_ingresos'!AI5) | AJ5: =IF('Registrar expedidas_ingresos'!AJ5="","",'Registrar expedidas_ingresos'!AJ5)
A6: =IF('Registrar expedidas_ingresos'!J6="",IF('Registrar expedidas_ingresos'!I6="","",YEAR('Registrar expedidas_ingresos'!I6)),YEAR('Registrar expedidas_ingresos'!J6)) | B6: =IF('Registrar expedidas_ingresos'!B6="","",'Registrar expedidas_ingresos'!B6) | C6: =IF('Registrar expedidas_ingresos'!C6="","",VLOOKUP(CONCATENATE("ACTIVIDAD",'Registrar expedidas_ingresos'!C6),'CODIGO-LITERAL'!C:D,2,FALSE)) | D6: =IF(OR(C6="C",C6="D"),"",IF(ISERROR(VLOOKUP(CONCATENATE(C6,'Registrar expedidas_ingresos'!D6),'CODIGO-LITERAL'!$C:$D,2,FALSE)),"",VLOOKUP(CONCATENATE(C6,'Registrar expedidas_ingresos'!D6),'CODIGO-LITERAL'!$C:$D,2,FALSE))) | E6: =IF('Registrar expedidas_ingresos'!E6="","",'Registrar expedidas_ingresos'!E6) | F6: =IF(ISERROR(VLOOKUP(CONCATENATE("TIPO FACTURA",'Registrar expedidas_ingresos'!F6),'CODIGO-LITERAL'!$C:$D,2,FALSE)),"",VLOOKUP(CONCATENATE("TIPO FACTURA",'Registrar expedidas_ingresos'!F6),'CODIGO-LITERAL'!$C:$D,2,FALSE)) | I6: =IF('Registrar expedidas_ingresos'!I6="","",'Registrar expedidas_ingresos'!I6) | J6: =IF('Registrar expedidas_ingresos'!J6="","",'Registrar expedidas_ingresos'!J6) | K6: =IF('Registrar expedidas_ingresos'!K6="","",'Registrar expedidas_ingresos'!K6) | L6: =IF('Registrar expedidas_ingresos'!L6="","",'Registrar expedidas_ingresos'!L6) | M6: =IF('Registrar expedidas_ingresos'!M6="","",'Registrar expedidas_ingresos'!M6) | N6: =IF(OR(F6="F2",LEFT('Registrar expedidas_ingresos'!N6,2)="01"),"",IF(ISERROR(VLOOKUP(CONCATENATE("TIPO NIF",'Registrar expedidas_ingresos'!N6),'CODIGO-LITERAL'!$C:$D,2,FALSE)),"",VLOOKUP(CONCATENATE("TIPO NIF",'Registrar expedidas_ingresos'!N6),'CODIGO-LITERAL'!$C:$D,2,FALSE))) | O6: =IF(OR('Registrar expedidas_ingresos'!O6="",N6="02",F6="F2"),"",'Registrar expedidas_ingresos'!O6) | P6: =IF('Registrar expedidas_ingresos'!P6="","",'Registrar expedidas_ingresos'!P6) | Q6: =IF(F6="F2","VENTAS A CONSUMIDOR FINAL",IF('Registrar expedidas_ingresos'!Q6="","",'Registrar expedidas_ingresos'!Q6)) | R6: =IF(F6="DV","02",IF(ISERROR(VLOOKUP(CONCATENATE("CLAVE OPERACION",'Registrar expedidas_ingresos'!R6),'CODIGO-LITERAL'!$C:$D,2,FALSE)),"",VLOOKUP(CONCATENATE("CLAVE OPERACION",'Registrar expedidas_ingresos'!R6),'CODIGO-LITERAL'!$C:$D,2,FALSE))) | S6: =IF(R6="03","S1", IF(R6="08","N2", IF(ISERROR(VLOOKUP(CONCATENATE("CALIFICACION OPERACION",'Registrar expedidas_ingresos'!S6),'CODIGO-LITERAL'!$C:$D,2,FALSE)),"",VLOOKUP(CONCATENATE("CALIFICACION OPERACION",'Registrar expedidas_ingresos'!S6),'CODIGO-LITERAL'!$C:$D,2,FALSE)))) | T6: =IF(R6="03","",IF(R6="08","",IF(ISERROR(VLOOKUP(CONCATENATE("OPERACION EXENTA",'Registrar expedidas_ingresos'!T6),'CODIGO-LITERAL'!$C:$D,2,FALSE)),"",VLOOKUP(CONCATENATE("OPERACION EXENTA",'Registrar expedidas_ingresos'!T6),'CODIGO-LITERAL'!$C:$D,2,FALSE)))) | U6: =IF(AND(S6="",T6=""),"",IF(S6="S1",ROUND(SUM(V6,X6,Z6),2),ROUND(V6,2))) | V6: =IF('Registrar expedidas_ingresos'!V6="","",ROUND('Registrar expedidas_ingresos'!V6,2)) | W6: =IF(S6="S2",0,IF('Registrar expedidas_ingresos'!W6="","",'Registrar expedidas_ingresos'!W6)) | X6: =IF(S6="S2",0,IF('Registrar expedidas_ingresos'!X6="","",ROUND('Registrar expedidas_ingresos'!X6,2))) | Y6: =IF('Registrar expedidas_ingresos'!Y6="","",'Registrar expedidas_ingresos'!Y6) | Z6: =IF('Registrar expedidas_ingresos'!Z6="","",ROUND('Registrar expedidas_ingresos'!Z6,2)) | AA6: =IF(R6<>"07","",IF('Registrar expedidas_ingresos'!AA6="","",'Registrar expedidas_ingresos'!AA6)) | AB6: =IF(R6<>"07","",IF('Registrar expedidas_ingresos'!AB6="","",'Registrar expedidas_ingresos'!AB6)) | AC6: =IF(R6<>"07","",IF(ISERROR(VLOOKUP(CONCATENATE("MEDIO UTILIZADO",'Registrar expedidas_ingresos'!AC6),'CODIGO-LITERAL'!$C:$D,2,FALSE)),"",VLOOKUP(CONCATENATE("MEDIO UTILIZADO",'Registrar expedidas_ingresos'!AC6),'CODIGO-LITERAL'!$C:$D,2,FALSE))) | AD6: =IF(R6<>"07","",IF('Registrar expedidas_ingresos'!AD6="","",'Registrar expedidas_ingresos'!AD6)) | AG6: =IF('Registrar expedidas_ingresos'!AG6="","",'Registrar expedidas_ingresos'!AG6) | AH6: =IF(ISERROR(VLOOKUP(CONCATENATE("SITUACION",'Registrar expedidas_ingresos'!AH6),'CODIGO-LITERAL'!$C:$D,2,FALSE)),"",VLOOKUP(CONCATENATE("SITUACION",'Registrar expedidas_ingresos'!AH6),'CODIGO-LITERAL'!$C:$D,2,FALSE)) | AI6: =IF('Registrar expedidas_ingresos'!AI6="","",'Registrar expedidas_ingresos'!AI6) | AJ6: =IF('Registrar expedidas_ingresos'!AJ6="","",'Registrar expedidas_ingresos'!AJ6)
A7: =IF('Registrar expedidas_ingresos'!J7="",IF('Registrar expedidas_ingresos'!I7="","",YEAR('Registrar expedidas_ingresos'!I7)),YEAR('Registrar expedidas_ingresos'!J7)) | B7: =IF('Registrar expedidas_ingresos'!B7="","",'Registrar expedidas_ingresos'!B7) | C7: =IF('Registrar expedidas_ingresos'!C7="","",VLOOKUP(CONCATENATE("ACTIVIDAD",'Registrar expedidas_ingresos'!C7),'CODIGO-LITERAL'!C:D,2,FALSE)) | D7: =IF(OR(C7="C",C7="D"),"",IF(ISERROR(VLOOKUP(CONCATENATE(C7,'Registrar expedidas_ingresos'!D7),'CODIGO-LITERAL'!$C:$D,2,FALSE)),"",VLOOKUP(CONCATENATE(C7,'Registrar expedidas_ingresos'!D7),'CODIGO-LITERAL'!$C:$D,2,FALSE))) | E7: =IF('Registrar expedidas_ingresos'!E7="","",'Registrar expedidas_ingresos'!E7) | F7: =IF(ISERROR(VLOOKUP(CONCATENATE("TIPO FACTURA",'Registrar expedidas_ingresos'!F7),'CODIGO-LITERAL'!$C:$D,2,FALSE)),"",VLOOKUP(CONCATENATE("TIPO FACTURA",'Registrar expedidas_ingresos'!F7),'CODIGO-LITERAL'!$C:$D,2,FALSE)) | I7: =IF('Registrar expedidas_ingresos'!I7="","",'Registrar expedidas_ingresos'!I7) | J7: =IF('Registrar expedidas_ingresos'!J7="","",'Registrar expedidas_ingresos'!J7) | K7: =IF('Registrar expedidas_ingresos'!K7="","",'Registrar expedidas_ingresos'!K7) | L7: =IF('Registrar expedidas_ingresos'!L7="","",'Registrar expedidas_ingresos'!L7) | M7: =IF('Registrar expedidas_ingresos'!M7="","",'Registrar expedidas_ingresos'!M7) | N7: =IF(OR(F7="F2",LEFT('Registrar expedidas_ingresos'!N7,2)="01"),"",IF(ISERROR(VLOOKUP(CONCATENATE("TIPO NIF",'Registrar expedidas_ingresos'!N7),'CODIGO-LITERAL'!$C:$D,2,FALSE)),"",VLOOKUP(CONCATENATE("TIPO NIF",'Registrar expedidas_ingresos'!N7),'CODIGO-LITERAL'!$C:$D,2,FALSE))) | O7: =IF(OR('Registrar expedidas_ingresos'!O7="",N7="02",F7="F2"),"",'Registrar expedidas_ingresos'!O7) | P7: =IF('Registrar expedidas_ingresos'!P7="","",'Registrar expedidas_ingresos'!P7) | Q7: =IF(F7="F2","VENTAS A CONSUMIDOR FINAL",IF('Registrar expedidas_ingresos'!Q7="","",'Registrar expedidas_ingresos'!Q7)) | R7: =IF(F7="DV","02",IF(ISERROR(VLOOKUP(CONCATENATE("CLAVE OPERACION",'Registrar expedidas_ingresos'!R7),'CODIGO-LITERAL'!$C:$D,2,FALSE)),"",VLOOKUP(CONCATENATE("CLAVE OPERACION",'Registrar expedidas_ingresos'!R7),'CODIGO-LITERAL'!$C:$D,2,FALSE))) | S7: =IF(R7="03","S1", IF(R7="08","N2", IF(ISERROR(VLOOKUP(CONCATENATE("CALIFICACION OPERACION",'Registrar expedidas_ingresos'!S7),'CODIGO-LITERAL'!$C:$D,2,FALSE)),"",VLOOKUP(CONCATENATE("CALIFICACION OPERACION",'Registrar expedidas_ingresos'!S7),'CODIGO-LITERAL'!$C:$D,2,FALSE)))) | T7: =IF(R7="03","",IF(R7="08","",IF(ISERROR(VLOOKUP(CONCATENATE("OPERACION EXENTA",'Registrar expedidas_ingresos'!T7),'CODIGO-LITERAL'!$C:$D,2,FALSE)),"",VLOOKUP(CONCATENATE("OPERACION EXENTA",'Registrar expedidas_ingresos'!T7),'CODIGO-LITERAL'!$C:$D,2,FALSE)))) | U7: =IF(AND(S7="",T7=""),"",IF(S7="S1",ROUND(SUM(V7,X7,Z7),2),ROUND(V7,2))) | V7: =IF('Registrar expedidas_ingresos'!V7="","",ROUND('Registrar expedidas_ingresos'!V7,2)) | W7: =IF(S7="S2",0,IF('Registrar expedidas_ingresos'!W7="","",'Registrar expedidas_ingresos'!W7)) | X7: =IF(S7="S2",0,IF('Registrar expedidas_ingresos'!X7="","",ROUND('Registrar expedidas_ingresos'!X7,2))) | Y7: =IF('Registrar expedidas_ingresos'!Y7="","",'Registrar expedidas_ingresos'!Y7) | Z7: =IF('Registrar expedidas_ingresos'!Z7="","",ROUND('Registrar expedidas_ingresos'!Z7,2)) | AA7: =IF(R7<>"07","",IF('Registrar expedidas_ingresos'!AA7="","",'Registrar expedidas_ingresos'!AA7)) | AB7: =IF(R7<>"07","",IF('Registrar expedidas_ingresos'!AB7="","",'Registrar expedidas_ingresos'!AB7)) | AC7: =IF(R7<>"07","",IF(ISERROR(VLOOKUP(CONCATENATE("MEDIO UTILIZADO",'Registrar expedidas_ingresos'!AC7),'CODIGO-LITERAL'!$C:$D,2,FALSE)),"",VLOOKUP(CONCATENATE("MEDIO UTILIZADO",'Registrar expedidas_ingresos'!AC7),'CODIGO-LITERAL'!$C:$D,2,FALSE))) | AD7: =IF(R7<>"07","",IF('Registrar expedidas_ingresos'!AD7="","",'Registrar expedidas_ingresos'!AD7)) | AG7: =IF('Registrar expedidas_ingresos'!AG7="","",'Registrar expedidas_ingresos'!AG7) | AH7: =IF(ISERROR(VLOOKUP(CONCATENATE("SITUACION",'Registrar expedidas_ingresos'!AH7),'CODIGO-LITERAL'!$C:$D,2,FALSE)),"",VLOOKUP(CONCATENATE("SITUACION",'Registrar expedidas_ingresos'!AH7),'CODIGO-LITERAL'!$C:$D,2,FALSE)) | AI7: =IF('Registrar expedidas_ingresos'!AI7="","",'Registrar expedidas_ingresos'!AI7) | AJ7: =IF('Registrar expedidas_ingresos'!AJ7="","",'Registrar expedidas_ingresos'!AJ7)
A8: =IF('Registrar expedidas_ingresos'!J8="",IF('Registrar expedidas_ingresos'!I8="","",YEAR('Registrar expedidas_ingresos'!I8)),YEAR('Registrar expedidas_ingresos'!J8)) | B8: =IF('Registrar expedidas_ingresos'!B8="","",'Registrar expedidas_ingresos'!B8) | C8: =IF('Registrar expedidas_ingresos'!C8="","",VLOOKUP(CONCATENATE("ACTIVIDAD",'Registrar expedidas_ingresos'!C8),'CODIGO-LITERAL'!C:D,2,FALSE)) | D8: =IF(OR(C8="C",C8="D"),"",IF(ISERROR(VLOOKUP(CONCATENATE(C8,'Registrar expedidas_ingresos'!D8),'CODIGO-LITERAL'!$C:$D,2,FALSE)),"",VLOOKUP(CONCATENATE(C8,'Registrar expedidas_ingresos'!D8),'CODIGO-LITERAL'!$C:$D,2,FALSE))) | E8: =IF('Registrar expedidas_ingresos'!E8="","",'Registrar expedidas_ingresos'!E8) | F8: =IF(ISERROR(VLOOKUP(CONCATENATE("TIPO FACTURA",'Registrar expedidas_ingresos'!F8),'CODIGO-LITERAL'!$C:$D,2,FALSE)),"",VLOOKUP(CONCATENATE("TIPO FACTURA",'Registrar expedidas_ingresos'!F8),'CODIGO-LITERAL'!$C:$D,2,FALSE)) | I8: =IF('Registrar expedidas_ingresos'!I8="","",'Registrar expedidas_ingresos'!I8) | J8: =IF('Registrar expedidas_ingresos'!J8="","",'Registrar expedidas_ingresos'!J8) | K8: =IF('Registrar expedidas_ingresos'!K8="","",'Registrar expedidas_ingresos'!K8) | L8: =IF('Registrar expedidas_ingresos'!L8="","",'Registrar expedidas_ingresos'!L8) | M8: =IF('Registrar expedidas_ingresos'!M8="","",'Registrar expedidas_ingresos'!M8) | N8: =IF(OR(F8="F2",LEFT('Registrar expedidas_ingresos'!N8,2)="01"),"",IF(ISERROR(VLOOKUP(CONCATENATE("TIPO NIF",'Registrar expedidas_ingresos'!N8),'CODIGO-LITERAL'!$C:$D,2,FALSE)),"",VLOOKUP(CONCATENATE("TIPO NIF",'Registrar expedidas_ingresos'!N8),'CODIGO-LITERAL'!$C:$D,2,FALSE))) | O8: =IF(OR('Registrar expedidas_ingresos'!O8="",N8="02",F8="F2"),"",'Registrar expedidas_ingresos'!O8) | P8: =IF('Registrar expedidas_ingresos'!P8="","",'Registrar expedidas_ingresos'!P8) | Q8: =IF(F8="F2","VENTAS A CONSUMIDOR FINAL",IF('Registrar expedidas_ingresos'!Q8="","",'Registrar expedidas_ingresos'!Q8)) | R8: =IF(F8="DV","02",IF(ISERROR(VLOOKUP(CONCATENATE("CLAVE OPERACION",'Registrar expedidas_ingresos'!R8),'CODIGO-LITERAL'!$C:$D,2,FALSE)),"",VLOOKUP(CONCATENATE("CLAVE OPERACION",'Registrar expedidas_ingresos'!R8),'CODIGO-LITERAL'!$C:$D,2,FALSE))) | S8: =IF(R8="03","S1", IF(R8="08","N2", IF(ISERROR(VLOOKUP(CONCATENATE("CALIFICACION OPERACION",'Registrar expedidas_ingresos'!S8),'CODIGO-LITERAL'!$C:$D,2,FALSE)),"",VLOOKUP(CONCATENATE("CALIFICACION OPERACION",'Registrar expedidas_ingresos'!S8),'CODIGO-LITERAL'!$C:$D,2,FALSE)))) | T8: =IF(R8="03","",IF(R8="08","",IF(ISERROR(VLOOKUP(CONCATENATE("OPERACION EXENTA",'Registrar expedidas_ingresos'!T8),'CODIGO-LITERAL'!$C:$D,2,FALSE)),"",VLOOKUP(CONCATENATE("OPERACION EXENTA",'Registrar expedidas_ingresos'!T8),'CODIGO-LITERAL'!$C:$D,2,FALSE)))) | U8: =IF(AND(S8="",T8=""),"",IF(S8="S1",ROUND(SUM(V8,X8,Z8),2),ROUND(V8,2))) | V8: =IF('Registrar expedidas_ingresos'!V8="","",ROUND('Registrar expedidas_ingresos'!V8,2)) | W8: =IF(S8="S2",0,IF('Registrar expedidas_ingresos'!W8="","",'Registrar expedidas_ingresos'!W8)) | X8: =IF(S8="S2",0,IF('Registrar expedidas_ingresos'!X8="","",ROUND('Registrar expedidas_ingresos'!X8,2))) | Y8: =IF('Registrar expedidas_ingresos'!Y8="","",'Registrar expedidas_ingresos'!Y8) | Z8: =IF('Registrar expedidas_ingresos'!Z8="","",ROUND('Registrar expedidas_ingresos'!Z8,2)) | AA8: =IF(R8<>"07","",IF('Registrar expedidas_ingresos'!AA8="","",'Registrar expedidas_ingresos'!AA8)) | AB8: =IF(R8<>"07","",IF('Registrar expedidas_ingresos'!AB8="","",'Registrar expedidas_ingresos'!AB8)) | AC8: =IF(R8<>"07","",IF(ISERROR(VLOOKUP(CONCATENATE("MEDIO UTILIZADO",'Registrar expedidas_ingresos'!AC8),'CODIGO-LITERAL'!$C:$D,2,FALSE)),"",VLOOKUP(CONCATENATE("MEDIO UTILIZADO",'Registrar expedidas_ingresos'!AC8),'CODIGO-LITERAL'!$C:$D,2,FALSE))) | AD8: =IF(R8<>"07","",IF('Registrar expedidas_ingresos'!AD8="","",'Registrar expedidas_ingresos'!AD8)) | AG8: =IF('Registrar expedidas_ingresos'!AG8="","",'Registrar expedidas_ingresos'!AG8) | AH8: =IF(ISERROR(VLOOKUP(CONCATENATE("SITUACION",'Registrar expedidas_ingresos'!AH8),'CODIGO-LITERAL'!$C:$D,2,FALSE)),"",VLOOKUP(CONCATENATE("SITUACION",'Registrar expedidas_ingresos'!AH8),'CODIGO-LITERAL'!$C:$D,2,FALSE)) | AI8: =IF('Registrar expedidas_ingresos'!AI8="","",'Registrar expedidas_ingresos'!AI8) | AJ8: =IF('Registrar expedidas_ingresos'!AJ8="","",'Registrar expedidas_ingresos'!AJ8)
A9: =IF('Registrar expedidas_ingresos'!J9="",IF('Registrar expedidas_ingresos'!I9="","",YEAR('Registrar expedidas_ingresos'!I9)),YEAR('Registrar expedidas_ingresos'!J9)) | B9: =IF('Registrar expedidas_ingresos'!B9="","",'Registrar expedidas_ingresos'!B9) | C9: =IF('Registrar expedidas_ingresos'!C9="","",VLOOKUP(CONCATENATE("ACTIVIDAD",'Registrar expedidas_ingresos'!C9),'CODIGO-LITERAL'!C:D,2,FALSE)) | D9: =IF(OR(C9="C",C9="D"),"",IF(ISERROR(VLOOKUP(CONCATENATE(C9,'Registrar expedidas_ingresos'!D9),'CODIGO-LITERAL'!$C:$D,2,FALSE)),"",VLOOKUP(CONCATENATE(C9,'Registrar expedidas_ingresos'!D9),'CODIGO-LITERAL'!$C:$D,2,FALSE))) | E9: =IF('Registrar expedidas_ingresos'!E9="","",'Registrar expedidas_ingresos'!E9) | F9: =IF(ISERROR(VLOOKUP(CONCATENATE("TIPO FACTURA",'Registrar expedidas_ingresos'!F9),'CODIGO-LITERAL'!$C:$D,2,FALSE)),"",VLOOKUP(CONCATENATE("TIPO FACTURA",'Registrar expedidas_ingresos'!F9),'CODIGO-LITERAL'!$C:$D,2,FALSE)) | I9: =IF('Registrar expedidas_ingresos'!I9="","",'Registrar expedidas_ingresos'!I9) | J9: =IF('Registrar expedidas_ingresos'!J9="","",'Registrar expedidas_ingresos'!J9) | K9: =IF('Registrar expedidas_ingresos'!K9="","",'Registrar expedidas_ingresos'!K9) | L9: =IF('Registrar expedidas_ingresos'!L9="","",'Registrar expedidas_ingresos'!L9) | M9: =IF('Registrar expedidas_ingresos'!M9="","",'Registrar expedidas_ingresos'!M9) | N9: =IF(OR(F9="F2",LEFT('Registrar expedidas_ingresos'!N9,2)="01"),"",IF(ISERROR(VLOOKUP(CONCATENATE("TIPO NIF",'Registrar expedidas_ingresos'!N9),'CODIGO-LITERAL'!$C:$D,2,FALSE)),"",VLOOKUP(CONCATENATE("TIPO NIF",'Registrar expedidas_ingresos'!N9),'CODIGO-LITERAL'!$C:$D,2,FALSE))) | O9: =IF(OR('Registrar expedidas_ingresos'!O9="",N9="02",F9="F2"),"",'Registrar expedidas_ingresos'!O9) | P9: =IF('Registrar expedidas_ingresos'!P9="","",'Registrar expedidas_ingresos'!P9) | Q9: =IF(F9="F2","VENTAS A CONSUMIDOR FINAL",IF('Registrar expedidas_ingresos'!Q9="","",'Registrar expedidas_ingresos'!Q9)) | R9: =IF(F9="DV","02",IF(ISERROR(VLOOKUP(CONCATENATE("CLAVE OPERACION",'Registrar expedidas_ingresos'!R9),'CODIGO-LITERAL'!$C:$D,2,FALSE)),"",VLOOKUP(CONCATENATE("CLAVE OPERACION",'Registrar expedidas_ingresos'!R9),'CODIGO-LITERAL'!$C:$D,2,FALSE))) | S9: =IF(R9="03","S1", IF(R9="08","N2", IF(ISERROR(VLOOKUP(CONCATENATE("CALIFICACION OPERACION",'Registrar expedidas_ingresos'!S9),'CODIGO-LITERAL'!$C:$D,2,FALSE)),"",VLOOKUP(CONCATENATE("CALIFICACION OPERACION",'Registrar expedidas_ingresos'!S9),'CODIGO-LITERAL'!$C:$D,2,FALSE)))) | T9: =IF(R9="03","",IF(R9="08","",IF(ISERROR(VLOOKUP(CONCATENATE("OPERACION EXENTA",'Registrar expedidas_ingresos'!T9),'CODIGO-LITERAL'!$C:$D,2,FALSE)),"",VLOOKUP(CONCATENATE("OPERACION EXENTA",'Registrar expedidas_ingresos'!T9),'CODIGO-LITERAL'!$C:$D,2,FALSE)))) | U9: =IF(AND(S9="",T9=""),"",IF(S9="S1",ROUND(SUM(V9,X9,Z9),2),ROUND(V9,2))) | V9: =IF('Registrar expedidas_ingresos'!V9="","",ROUND('Registrar expedidas_ingresos'!V9,2)) | W9: =IF(S9="S2",0,IF('Registrar expedidas_ingresos'!W9="","",'Registrar expedidas_ingresos'!W9)) | X9: =IF(S9="S2",0,IF('Registrar expedidas_ingresos'!X9="","",ROUND('Registrar expedidas_ingresos'!X9,2))) | Y9: =IF('Registrar expedidas_ingresos'!Y9="","",'Registrar expedidas_ingresos'!Y9) | Z9: =IF('Registrar expedidas_ingresos'!Z9="","",ROUND('Registrar expedidas_ingresos'!Z9,2)) | AA9: =IF(R9<>"07","",IF('Registrar expedidas_ingresos'!AA9="","",'Registrar expedidas_ingresos'!AA9)) | AB9: =IF(R9<>"07","",IF('Registrar expedidas_ingresos'!AB9="","",'Registrar expedidas_ingresos'!AB9)) | AC9: =IF(R9<>"07","",IF(ISERROR(VLOOKUP(CONCATENATE("MEDIO UTILIZADO",'Registrar expedidas_ingresos'!AC9),'CODIGO-LITERAL'!$C:$D,2,FALSE)),"",VLOOKUP(CONCATENATE("MEDIO UTILIZADO",'Registrar expedidas_ingresos'!AC9),'CODIGO-LITERAL'!$C:$D,2,FALSE))) | AD9: =IF(R9<>"07","",IF('Registrar expedidas_ingresos'!AD9="","",'Registrar expedidas_ingresos'!AD9)) | AG9: =IF('Registrar expedidas_ingresos'!AG9="","",'Registrar expedidas_ingresos'!AG9) | AH9: =IF(ISERROR(VLOOKUP(CONCATENATE("SITUACION",'Registrar expedidas_ingresos'!AH9),'CODIGO-LITERAL'!$C:$D,2,FALSE)),"",VLOOKUP(CONCATENATE("SITUACION",'Registrar expedidas_ingresos'!AH9),'CODIGO-LITERAL'!$C:$D,2,FALSE)) | AI9: =IF('Registrar expedidas_ingresos'!AI9="","",'Registrar expedidas_ingresos'!AI9) | AJ9: =IF('Registrar expedidas_ingresos'!AJ9="","",'Registrar expedidas_ingresos'!AJ9)
A10: =IF('Registrar expedidas_ingresos'!J10="",IF('Registrar expedidas_ingresos'!I10="","",YEAR('Registrar expedidas_ingresos'!I10)),YEAR('Registrar expedidas_ingresos'!J10)) | B10: =IF('Registrar expedidas_ingresos'!B10="","",'Registrar expedidas_ingresos'!B10) | C10: =IF('Registrar expedidas_ingresos'!C10="","",VLOOKUP(CONCATENATE("ACTIVIDAD",'Registrar expedidas_ingresos'!C10),'CODIGO-LITERAL'!C:D,2,FALSE)) | D10: =IF(OR(C10="C",C10="D"),"",IF(ISERROR(VLOOKUP(CONCATENATE(C10,'Registrar expedidas_ingresos'!D10),'CODIGO-LITERAL'!$C:$D,2,FALSE)),"",VLOOKUP(CONCATENATE(C10,'Registrar expedidas_ingresos'!D10),'CODIGO-LITERAL'!$C:$D,2,FALSE))) | E10: =IF('Registrar expedidas_ingresos'!E10="","",'Registrar expedidas_ingresos'!E10) | F10: =IF(ISERROR(VLOOKUP(CONCATENATE("TIPO FACTURA",'Registrar expedidas_ingresos'!F10),'CODIGO-LITERAL'!$C:$D,2,FALSE)),"",VLOOKUP(CONCATENATE("TIPO FACTURA",'Registrar expedidas_ingresos'!F10),'CODIGO-LITERAL'!$C:$D,2,FALSE)) | I10: =IF('Registrar expedidas_ingresos'!I10="","",'Registrar expedidas_ingresos'!I10) | J10: =IF('Registrar expedidas_ingresos'!J10="","",'Registrar expedidas_ingresos'!J10) | K10: =IF('Registrar expedidas_ingresos'!K10="","",'Registrar expedidas_ingresos'!K10) | L10: =IF('Registrar expedidas_ingresos'!L10="","",'Registrar expedidas_ingresos'!L10) | M10: =IF('Registrar expedidas_ingresos'!M10="","",'Registrar expedidas_ingresos'!M10) | N10: =IF(OR(F10="F2",LEFT('Registrar expedidas_ingresos'!N10,2)="01"),"",IF(ISERROR(VLOOKUP(CONCATENATE("TIPO NIF",'Registrar expedidas_ingresos'!N10),'CODIGO-LITERAL'!$C:$D,2,FALSE)),"",VLOOKUP(CONCATENATE("TIPO NIF",'Registrar expedidas_ingresos'!N10),'CODIGO-LITERAL'!$C:$D,2,FALSE))) | O10: =IF(OR('Registrar expedidas_ingresos'!O10="",N10="02",F10="F2"),"",'Registrar expedidas_ingresos'!O10) | P10: =IF('Registrar expedidas_ingresos'!P10="","",'Registrar expedidas_ingresos'!P10) | Q10: =IF(F10="F2","VENTAS A CONSUMIDOR FINAL",IF('Registrar expedidas_ingresos'!Q10="","",'Registrar expedidas_ingresos'!Q10)) | R10: =IF(F10="DV","02",IF(ISERROR(VLOOKUP(CONCATENATE("CLAVE OPERACION",'Registrar expedidas_ingresos'!R10),'CODIGO-LITERAL'!$C:$D,2,FALSE)),"",VLOOKUP(CONCATENATE("CLAVE OPERACION",'Registrar expedidas_ingresos'!R10),'CODIGO-LITERAL'!$C:$D,2,FALSE))) | S10: =IF(R10="03","S1", IF(R10="08","N2", IF(ISERROR(VLOOKUP(CONCATENATE("CALIFICACION OPERACION",'Registrar expedidas_ingresos'!S10),'CODIGO-LITERAL'!$C:$D,2,FALSE)),"",VLOOKUP(CONCATENATE("CALIFICACION OPERACION",'Registrar expedidas_ingresos'!S10),'CODIGO-LITERAL'!$C:$D,2,FALSE)))) | T10: =IF(R10="03","",IF(R10="08","",IF(ISERROR(VLOOKUP(CONCATENATE("OPERACION EXENTA",'Registrar expedidas_ingresos'!T10),'CODIGO-LITERAL'!$C:$D,2,FALSE)),"",VLOOKUP(CONCATENATE("OPERACION EXENTA",'Registrar expedidas_ingresos'!T10),'CODIGO-LITERAL'!$C:$D,2,FALSE)))) | U10: =IF(AND(S10="",T10=""),"",IF(S10="S1",ROUND(SUM(V10,X10,Z10),2),ROUND(V10,2))) | V10: =IF('Registrar expedidas_ingresos'!V10="","",ROUND('Registrar expedidas_ingresos'!V10,2)) | W10: =IF(S10="S2",0,IF('Registrar expedidas_ingresos'!W10="","",'Registrar expedidas_ingresos'!W10)) | X10: =IF(S10="S2",0,IF('Registrar expedidas_ingresos'!X10="","",ROUND('Registrar expedidas_ingresos'!X10,2))) | Y10: =IF('Registrar expedidas_ingresos'!Y10="","",'Registrar expedidas_ingresos'!Y10) | Z10: =IF('Registrar expedidas_ingresos'!Z10="","",ROUND('Registrar expedidas_ingresos'!Z10,2)) | AA10: =IF(R10<>"07","",IF('Registrar expedidas_ingresos'!AA10="","",'Registrar expedidas_ingresos'!AA10)) | AB10: =IF(R10<>"07","",IF('Registrar expedidas_ingresos'!AB10="","",'Registrar expedidas_ingresos'!AB10)) | AC10: =IF(R10<>"07","",IF(ISERROR(VLOOKUP(CONCATENATE("MEDIO UTILIZADO",'Registrar expedidas_ingresos'!AC10),'CODIGO-LITERAL'!$C:$D,2,FALSE)),"",VLOOKUP(CONCATENATE("MEDIO UTILIZADO",'Registrar expedidas_ingresos'!AC10),'CODIGO-LITERAL'!$C:$D,2,FALSE))) | AD10: =IF(R10<>"07","",IF('Registrar expedidas_ingresos'!AD10="","",'Registrar expedidas_ingresos'!AD10)) | AG10: =IF('Registrar expedidas_ingresos'!AG10="","",'Registrar expedidas_ingresos'!AG10) | AH10: =IF(ISERROR(VLOOKUP(CONCATENATE("SITUACION",'Registrar expedidas_ingresos'!AH10),'CODIGO-LITERAL'!$C:$D,2,FALSE)),"",VLOOKUP(CONCATENATE("SITUACION",'Registrar expedidas_ingresos'!AH10),'CODIGO-LITERAL'!$C:$D,2,FALSE)) | AI10: =IF('Registrar expedidas_ingresos'!AI10="","",'Registrar expedidas_ingresos'!AI10) | AJ10: =IF('Registrar expedidas_ingresos'!AJ10="","",'Registrar expedidas_ingresos'!AJ10)
A11: =IF('Registrar expedidas_ingresos'!J11="",IF('Registrar expedidas_ingresos'!I11="","",YEAR('Registrar expedidas_ingresos'!I11)),YEAR('Registrar expedidas_ingresos'!J11)) | B11: =IF('Registrar expedidas_ingresos'!B11="","",'Registrar expedidas_ingresos'!B11) | C11: =IF('Registrar expedidas_ingresos'!C11="","",VLOOKUP(CONCATENATE("ACTIVIDAD",'Registrar expedidas_ingresos'!C11),'CODIGO-LITERAL'!C:D,2,FALSE)) | D11: =IF(OR(C11="C",C11="D"),"",IF(ISERROR(VLOOKUP(CONCATENATE(C11,'Registrar expedidas_ingresos'!D11),'CODIGO-LITERAL'!$C:$D,2,FALSE)),"",VLOOKUP(CONCATENATE(C11,'Registrar expedidas_ingresos'!D11),'CODIGO-LITERAL'!$C:$D,2,FALSE))) | E11: =IF('Registrar expedidas_ingresos'!E11="","",'Registrar expedidas_ingresos'!E11) | F11: =IF(ISERROR(VLOOKUP(CONCATENATE("TIPO FACTURA",'Registrar expedidas_ingresos'!F11),'CODIGO-LITERAL'!$C:$D,2,FALSE)),"",VLOOKUP(CONCATENATE("TIPO FACTURA",'Registrar expedidas_ingresos'!F11),'CODIGO-LITERAL'!$C:$D,2,FALSE)) | I11: =IF('Registrar expedidas_ingresos'!I11="","",'Registrar expedidas_ingresos'!I11) | J11: =IF('Registrar expedidas_ingresos'!J11="","",'Registrar expedidas_ingresos'!J11) | K11: =IF('Registrar expedidas_ingresos'!K11="","",'Registrar expedidas_ingresos'!K11) | L11: =IF('Registrar expedidas_ingresos'!L11="","",'Registrar expedidas_ingresos'!L11) | M11: =IF('Registrar expedidas_ingresos'!M11="","",'Registrar expedidas_ingresos'!M11) | N11: =IF(OR(F11="F2",LEFT('Registrar expedidas_ingresos'!N11,2)="01"),"",IF(ISERROR(VLOOKUP(CONCATENATE("TIPO NIF",'Registrar expedidas_ingresos'!N11),'CODIGO-LITERAL'!$C:$D,2,FALSE)),"",VLOOKUP(CONCATENATE("TIPO NIF",'Registrar expedidas_ingresos'!N11),'CODIGO-LITERAL'!$C:$D,2,FALSE))) | O11: =IF(OR('Registrar expedidas_ingresos'!O11="",N11="02",F11="F2"),"",'Registrar expedidas_ingresos'!O11) | P11: =IF('Registrar expedidas_ingresos'!P11="","",'Registrar expedidas_ingresos'!P11) | Q11: =IF(F11="F2","VENTAS A CONSUMIDOR FINAL",IF('Registrar expedidas_ingresos'!Q11="","",'Registrar expedidas_ingresos'!Q11)) | R11: =IF(F11="DV","02",IF(ISERROR(VLOOKUP(CONCATENATE("CLAVE OPERACION",'Registrar expedidas_ingresos'!R11),'CODIGO-LITERAL'!$C:$D,2,FALSE)),"",VLOOKUP(CONCATENATE("CLAVE OPERACION",'Registrar expedidas_ingresos'!R11),'CODIGO-LITERAL'!$C:$D,2,FALSE))) | S11: =IF(R11="03","S1", IF(R11="08","N2", IF(ISERROR(VLOOKUP(CONCATENATE("CALIFICACION OPERACION",'Registrar expedidas_ingresos'!S11),'CODIGO-LITERAL'!$C:$D,2,FALSE)),"",VLOOKUP(CONCATENATE("CALIFICACION OPERACION",'Registrar expedidas_ingresos'!S11),'CODIGO-LITERAL'!$C:$D,2,FALSE)))) | T11: =IF(R11="03","",IF(R11="08","",IF(ISERROR(VLOOKUP(CONCATENATE("OPERACION EXENTA",'Registrar expedidas_ingresos'!T11),'CODIGO-LITERAL'!$C:$D,2,FALSE)),"",VLOOKUP(CONCATENATE("OPERACION EXENTA",'Registrar expedidas_ingresos'!T11),'CODIGO-LITERAL'!$C:$D,2,FALSE)))) | U11: =IF(AND(S11="",T11=""),"",IF(S11="S1",ROUND(SUM(V11,X11,Z11),2),ROUND(V11,2))) | V11: =IF('Registrar expedidas_ingresos'!V11="","",ROUND('Registrar expedidas_ingresos'!V11,2)) | W11: =IF(S11="S2",0,IF('Registrar expedidas_ingresos'!W11="","",'Registrar expedidas_ingresos'!W11)) | X11: =IF(S11="S2",0,IF('Registrar expedidas_ingresos'!X11="","",ROUND('Registrar expedidas_ingresos'!X11,2))) | Y11: =IF('Registrar expedidas_ingresos'!Y11="","",'Registrar expedidas_ingresos'!Y11) | Z11: =IF('Registrar expedidas_ingresos'!Z11="","",ROUND('Registrar expedidas_ingresos'!Z11,2)) | AA11: =IF(R11<>"07","",IF('Registrar expedidas_ingresos'!AA11="","",'Registrar expedidas_ingresos'!AA11)) | AB11: =IF(R11<>"07","",IF('Registrar expedidas_ingresos'!AB11="","",'Registrar expedidas_ingresos'!AB11)) | AC11: =IF(R11<>"07","",IF(ISERROR(VLOOKUP(CONCATENATE("MEDIO UTILIZADO",'Registrar expedidas_ingresos'!AC11),'CODIGO-LITERAL'!$C:$D,2,FALSE)),"",VLOOKUP(CONCATENATE("MEDIO UTILIZADO",'Registrar expedidas_ingresos'!AC11),'CODIGO-LITERAL'!$C:$D,2,FALSE))) | AD11: =IF(R11<>"07","",IF('Registrar expedidas_ingresos'!AD11="","",'Registrar expedidas_ingresos'!AD11)) | AG11: =IF('Registrar expedidas_ingresos'!AG11="","",'Registrar expedidas_ingresos'!AG11) | AH11: =IF(ISERROR(VLOOKUP(CONCATENATE("SITUACION",'Registrar expedidas_ingresos'!AH11),'CODIGO-LITERAL'!$C:$D,2,FALSE)),"",VLOOKUP(CONCATENATE("SITUACION",'Registrar expedidas_ingresos'!AH11),'CODIGO-LITERAL'!$C:$D,2,FALSE)) | AI11: =IF('Registrar expedidas_ingresos'!AI11="","",'Registrar expedidas_ingresos'!AI11) | AJ11: =IF('Registrar expedidas_ingresos'!AJ11="","",'Registrar expedidas_ingresos'!AJ11)
A12: =IF('Registrar expedidas_ingresos'!J12="",IF('Registrar expedidas_ingresos'!I12="","",YEAR('Registrar expedidas_ingresos'!I12)),YEAR('Registrar expedidas_ingresos'!J12)) | B12: =IF('Registrar expedidas_ingresos'!B12="","",'Registrar expedidas_ingresos'!B12) | C12: =IF('Registrar expedidas_ingresos'!C12="","",VLOOKUP(CONCATENATE("ACTIVIDAD",'Registrar expedidas_ingresos'!C12),'CODIGO-LITERAL'!C:D,2,FALSE)) | D12: =IF(OR(C12="C",C12="D"),"",IF(ISERROR(VLOOKUP(CONCATENATE(C12,'Registrar expedidas_ingresos'!D12),'CODIGO-LITERAL'!$C:$D,2,FALSE)),"",VLOOKUP(CONCATENATE(C12,'Registrar expedidas_ingresos'!D12),'CODIGO-LITERAL'!$C:$D,2,FALSE))) | E12: =IF('Registrar expedidas_ingresos'!E12="","",'Registrar expedidas_ingresos'!E12) | F12: =IF(ISERROR(VLOOKUP(CONCATENATE("TIPO FACTURA",'Registrar expedidas_ingresos'!F12),'CODIGO-LITERAL'!$C:$D,2,FALSE)),"",VLOOKUP(CONCATENATE("TIPO FACTURA",'Registrar expedidas_ingresos'!F12),'CODIGO-LITERAL'!$C:$D,2,FALSE)) | I12: =IF('Registrar expedidas_ingresos'!I12="","",'Registrar expedidas_ingresos'!I12) | J12: =IF('Registrar expedidas_ingresos'!J12="","",'Registrar expedidas_ingresos'!J12) | K12: =IF('Registrar expedidas_ingresos'!K12="","",'Registrar expedidas_ingresos'!K12) | L12: =IF('Registrar expedidas_ingresos'!L12="","",'Registrar expedidas_ingresos'!L12) | M12: =IF('Registrar expedidas_ingresos'!M12="","",'Registrar expedidas_ingresos'!M12) | N12: =IF(OR(F12="F2",LEFT('Registrar expedidas_ingresos'!N12,2)="01"),"",IF(ISERROR(VLOOKUP(CONCATENATE("TIPO NIF",'Registrar expedidas_ingresos'!N12),'CODIGO-LITERAL'!$C:$D,2,FALSE)),"",VLOOKUP(CONCATENATE("TIPO NIF",'Registrar expedidas_ingresos'!N12),'CODIGO-LITERAL'!$C:$D,2,FALSE))) | O12: =IF(OR('Registrar expedidas_ingresos'!O12="",N12="02",F12="F2"),"",'Registrar expedidas_ingresos'!O12) | P12: =IF('Registrar expedidas_ingresos'!P12="","",'Registrar expedidas_ingresos'!P12) | Q12: =IF(F12="F2","VENTAS A CONSUMIDOR FINAL",IF('Registrar expedidas_ingresos'!Q12="","",'Registrar expedidas_ingresos'!Q12)) | R12: =IF(F12="DV","02",IF(ISERROR(VLOOKUP(CONCATENATE("CLAVE OPERACION",'Registrar expedidas_ingresos'!R12),'CODIGO-LITERAL'!$C:$D,2,FALSE)),"",VLOOKUP(CONCATENATE("CLAVE OPERACION",'Registrar expedidas_ingresos'!R12),'CODIGO-LITERAL'!$C:$D,2,FALSE))) | S12: =IF(R12="03","S1", IF(R12="08","N2", IF(ISERROR(VLOOKUP(CONCATENATE("CALIFICACION OPERACION",'Registrar expedidas_ingresos'!S12),'CODIGO-LITERAL'!$C:$D,2,FALSE)),"",VLOOKUP(CONCATENATE("CALIFICACION OPERACION",'Registrar expedidas_ingresos'!S12),'CODIGO-LITERAL'!$C:$D,2,FALSE)))) | T12: =IF(R12="03","",IF(R12="08","",IF(ISERROR(VLOOKUP(CONCATENATE("OPERACION EXENTA",'Registrar expedidas_ingresos'!T12),'CODIGO-LITERAL'!$C:$D,2,FALSE)),"",VLOOKUP(CONCATENATE("OPERACION EXENTA",'Registrar expedidas_ingresos'!T12),'CODIGO-LITERAL'!$C:$D,2,FALSE)))) | U12: =IF(AND(S12="",T12=""),"",IF(S12="S1",ROUND(SUM(V12,X12,Z12),2),ROUND(V12,2))) | V12: =IF('Registrar expedidas_ingresos'!V12="","",ROUND('Registrar expedidas_ingresos'!V12,2)) | W12: =IF(S12="S2",0,IF('Registrar expedidas_ingresos'!W12="","",'Registrar expedidas_ingresos'!W12)) | X12: =IF(S12="S2",0,IF('Registrar expedidas_ingresos'!X12="","",ROUND('Registrar expedidas_ingresos'!X12,2))) | Y12: =IF('Registrar expedidas_ingresos'!Y12="","",'Registrar expedidas_ingresos'!Y12) | Z12: =IF('Registrar expedidas_ingresos'!Z12="","",ROUND('Registrar expedidas_ingresos'!Z12,2)) | AA12: =IF(R12<>"07","",IF('Registrar expedidas_ingresos'!AA12="","",'Registrar expedidas_ingresos'!AA12)) | AB12: =IF(R12<>"07","",IF('Registrar expedidas_ingresos'!AB12="","",'Registrar expedidas_ingresos'!AB12)) | AC12: =IF(R12<>"07","",IF(ISERROR(VLOOKUP(CONCATENATE("MEDIO UTILIZADO",'Registrar expedidas_ingresos'!AC12),'CODIGO-LITERAL'!$C:$D,2,FALSE)),"",VLOOKUP(CONCATENATE("MEDIO UTILIZADO",'Registrar expedidas_ingresos'!AC12),'CODIGO-LITERAL'!$C:$D,2,FALSE))) | AD12: =IF(R12<>"07","",IF('Registrar expedidas_ingresos'!AD12="","",'Registrar expedidas_ingresos'!AD12)) | AG12: =IF('Registrar expedidas_ingresos'!AG12="","",'Registrar expedidas_ingresos'!AG12) | AH12: =IF(ISERROR(VLOOKUP(CONCATENATE("SITUACION",'Registrar expedidas_ingresos'!AH12),'CODIGO-LITERAL'!$C:$D,2,FALSE)),"",VLOOKUP(CONCATENATE("SITUACION",'Registrar expedidas_ingresos'!AH12),'CODIGO-LITERAL'!$C:$D,2,FALSE)) | AI12: =IF('Registrar expedidas_ingresos'!AI12="","",'Registrar expedidas_ingresos'!AI12) | AJ12: =IF('Registrar expedidas_ingresos'!AJ12="","",'Registrar expedidas_ingresos'!AJ12)
A13: =IF('Registrar expedidas_ingresos'!J13="",IF('Registrar expedidas_ingresos'!I13="","",YEAR('Registrar expedidas_ingresos'!I13)),YEAR('Registrar expedidas_ingresos'!J13)) | B13: =IF('Registrar expedidas_ingresos'!B13="","",'Registrar expedidas_ingresos'!B13) | C13: =IF('Registrar expedidas_ingresos'!C13="","",VLOOKUP(CONCATENATE("ACTIVIDAD",'Registrar expedidas_ingresos'!C13),'CODIGO-LITERAL'!C:D,2,FALSE)) | D13: =IF(OR(C13="C",C13="D"),"",IF(ISERROR(VLOOKUP(CONCATENATE(C13,'Registrar expedidas_ingresos'!D13),'CODIGO-LITERAL'!$C:$D,2,FALSE)),"",VLOOKUP(CONCATENATE(C13,'Registrar expedidas_ingresos'!D13),'CODIGO-LITERAL'!$C:$D,2,FALSE))) | E13: =IF('Registrar expedidas_ingresos'!E13="","",'Registrar expedidas_ingresos'!E13) | F13: =IF(ISERROR(VLOOKUP(CONCATENATE("TIPO FACTURA",'Registrar expedidas_ingresos'!F13),'CODIGO-LITERAL'!$C:$D,2,FALSE)),"",VLOOKUP(CONCATENATE("TIPO FACTURA",'Registrar expedidas_ingresos'!F13),'CODIGO-LITERAL'!$C:$D,2,FALSE)) | I13: =IF('Registrar expedidas_ingresos'!I13="","",'Registrar expedidas_ingresos'!I13) | J13: =IF('Registrar expedidas_ingresos'!J13="","",'Registrar expedidas_ingresos'!J13) | K13: =IF('Registrar expedidas_ingresos'!K13="","",'Registrar expedidas_ingresos'!K13) | L13: =IF('Registrar expedidas_ingresos'!L13="","",'Registrar expedidas_ingresos'!L13) | M13: =IF('Registrar expedidas_ingresos'!M13="","",'Registrar expedidas_ingresos'!M13) | N13: =IF(OR(F13="F2",LEFT('Registrar expedidas_ingresos'!N13,2)="01"),"",IF(ISERROR(VLOOKUP(CONCATENATE("TIPO NIF",'Registrar expedidas_ingresos'!N13),'CODIGO-LITERAL'!$C:$D,2,FALSE)),"",VLOOKUP(CONCATENATE("TIPO NIF",'Registrar expedidas_ingresos'!N13),'CODIGO-LITERAL'!$C:$D,2,FALSE))) | O13: =IF(OR('Registrar expedidas_ingresos'!O13="",N13="02",F13="F2"),"",'Registrar expedidas_ingresos'!O13) | P13: =IF('Registrar expedidas_ingresos'!P13="","",'Registrar expedidas_ingresos'!P13) | Q13: =IF(F13="F2","VENTAS A CONSUMIDOR FINAL",IF('Registrar expedidas_ingresos'!Q13="","",'Registrar expedidas_ingresos'!Q13)) | R13: =IF(F13="DV","02",IF(ISERROR(VLOOKUP(CONCATENATE("CLAVE OPERACION",'Registrar expedidas_ingresos'!R13),'CODIGO-LITERAL'!$C:$D,2,FALSE)),"",VLOOKUP(CONCATENATE("CLAVE OPERACION",'Registrar expedidas_ingresos'!R13),'CODIGO-LITERAL'!$C:$D,2,FALSE))) | S13: =IF(R13="03","S1", IF(R13="08","N2", IF(ISERROR(VLOOKUP(CONCATENATE("CALIFICACION OPERACION",'Registrar expedidas_ingresos'!S13),'CODIGO-LITERAL'!$C:$D,2,FALSE)),"",VLOOKUP(CONCATENATE("CALIFICACION OPERACION",'Registrar expedidas_ingresos'!S13),'CODIGO-LITERAL'!$C:$D,2,FALSE)))) | T13: =IF(R13="03","",IF(R13="08","",IF(ISERROR(VLOOKUP(CONCATENATE("OPERACION EXENTA",'Registrar expedidas_ingresos'!T13),'CODIGO-LITERAL'!$C:$D,2,FALSE)),"",VLOOKUP(CONCATENATE("OPERACION EXENTA",'Registrar expedidas_ingresos'!T13),'CODIGO-LITERAL'!$C:$D,2,FALSE)))) | U13: =IF(AND(S13="",T13=""),"",IF(S13="S1",ROUND(SUM(V13,X13,Z13),2),ROUND(V13,2))) | V13: =IF('Registrar expedidas_ingresos'!V13="","",ROUND('Registrar expedidas_ingresos'!V13,2)) | W13: =IF(S13="S2",0,IF('Registrar expedidas_ingresos'!W13="","",'Registrar expedidas_ingresos'!W13)) | X13: =IF(S13="S2",0,IF('Registrar expedidas_ingresos'!X13="","",ROUND('Registrar expedidas_ingresos'!X13,2))) | Y13: =IF('Registrar expedidas_ingresos'!Y13="","",'Registrar expedidas_ingresos'!Y13) | Z13: =IF('Registrar expedidas_ingresos'!Z13="","",ROUND('Registrar expedidas_ingresos'!Z13,2)) | AA13: =IF(R13<>"07","",IF('Registrar expedidas_ingresos'!AA13="","",'Registrar expedidas_ingresos'!AA13)) | AB13: =IF(R13<>"07","",IF('Registrar expedidas_ingresos'!AB13="","",'Registrar expedidas_ingresos'!AB13)) | AC13: =IF(R13<>"07","",IF(ISERROR(VLOOKUP(CONCATENATE("MEDIO UTILIZADO",'Registrar expedidas_ingresos'!AC13),'CODIGO-LITERAL'!$C:$D,2,FALSE)),"",VLOOKUP(CONCATENATE("MEDIO UTILIZADO",'Registrar expedidas_ingresos'!AC13),'CODIGO-LITERAL'!$C:$D,2,FALSE))) | AD13: =IF(R13<>"07","",IF('Registrar expedidas_ingresos'!AD13="","",'Registrar expedidas_ingresos'!AD13)) | AG13: =IF('Registrar expedidas_ingresos'!AG13="","",'Registrar expedidas_ingresos'!AG13) | AH13: =IF(ISERROR(VLOOKUP(CONCATENATE("SITUACION",'Registrar expedidas_ingresos'!AH13),'CODIGO-LITERAL'!$C:$D,2,FALSE)),"",VLOOKUP(CONCATENATE("SITUACION",'Registrar expedidas_ingresos'!AH13),'CODIGO-LITERAL'!$C:$D,2,FALSE)) | AI13: =IF('Registrar expedidas_ingresos'!AI13="","",'Registrar expedidas_ingresos'!AI13) | AJ13: =IF('Registrar expedidas_ingresos'!AJ13="","",'Registrar expedidas_ingresos'!AJ13)
